<?xml version="1.0" ?>
<robot name="cube_bot">
  <link name="world"/>
  <link name="cube">
    <visual>
      <geometry>
        <box size="0.5 0.5 0.5"/>
      </geometry>
      <origin xyz="0 0 0.25"/>
      <material name="blue">
        <color rgba="0 0 0.8 1"/>
      </material>
    </visual>
    <inertial>
      <mass value="1"/>
      <inertia ixx="1.0" ixy="0.0" ixz="0.0" iyy="1.0" iyz="0.0" izz="1.0"/>
    </inertial>
  </link>

  <gazebo reference="cube">
    <gravity>0</gravity>
  </gazebo>

  <joint name="world_to_cube" type="planar">
    <axis xyz="1 0 0"/>
    <origin xyz="0.0 0.0 0.0"/>
    <parent link="world"/>
    <child link="cube"/>
    <limit effort="1000.0" lower="-15" upper="15" velocity="30"/>
    <dynamics damping="0.0" friction="0.0"/>
  </joint>

  <gazebo>
    <plugin name="object_controller" filename="libgazebo_ros_planar_move.so">
      <parameters>$(find cube_sim)/config/cubic_joint_trajectory_controller.yaml</parameters>
    </plugin>
  </gazebo>
</robot>